Workbook

Sheet 00_Surum_Gecmisi
A1: Sürüm Geçmişi
A2: Her geliştirme yeni sürüm olarak buraya işlenir. Güncel sürüm: v5 (2026-10-06).
A4: Sürüm | B4: Tarih | C4: Ne değişti | D4: Neden
A5: v1 | B5: 2026-10-02 | C5: İlk üretim. Dokümanın kendi isimlendirmesi (snake_case, uuid, numeric(20,6)) birebir Excel'e aktarıldı. 19 tablo + ilişki sheet'i. | D5: Dokümanın veri modelini görünür kılmak
A6: v2 | B6: 2026-10-02 | C6: Tüm tablo/kolon adları ve tipler NetTrexMM + NetTrex.OptionsFX konvansiyonuna çevrildi: Def/Txn prefix, PascalCase, uuid→int/bigint, numeric(20,6)→decimal(38,10), timestamptz→datetime, jsonb→nvarchar(MAX). SettlementType/PaymentInstructionType MM'de var olan tablolara FK'ye çevrildi. | D6: Kullanıcı dokümanın Postgres tarzı isimlendirmesini kullanmak istemedi; ev konvansiyonu esas alındı
A7: v3 | B7: 2026-10-02 | C7: Self-review bulgularının tamamı kapatıldı + DDL/repository üretimine hazır hale getirildi: • TÜM PK'ler bigint (ofis kuralı) • Her tablo için Id üretim stratejisi netleşti (DefNumberGen vs IDENTITY) • Constraint/Index sheet'i eklendi (PK_/UQ_/IX_/DF_ adlarıyla) • DB Nesneleri sheet'i eklendi (History+Trigger, DefNumberGen, FlowSet/FlowTransition, DefCountMonitoring+SP, FrameworkParameter, Menü) • Sabitler/Enum sheet'i eklendi (StateId bitmask, ActionId, tüm kod listeleri) • Tip Kuralları sheet'i eklendi • Tablo sheet'lerine Default / Index-Constraint / FK Hedefi kolonları eklendi • FlowEntity/MakerCheckerEntity audit blokları gerçek emsalden (TxnTawarruq) eklendi • Eşzamanlılık: TxnCollateralPosition opsiyonel değil ZORUNLU oldu | D7: Kullanıcı review istedi; 3 ciddi açık (Id üretimi, constraint listesi eksikliği, eşzamanlılık) + ofis tip kuralları (long Id, float/double yasak) ve SP/constraint/fonksiyon araştırması
A8: v4 | B8: 2026-10-04 | C8: 🔴 v3'ÜN BİR KARARI ÇÜRÜTÜLDÜ + fazla kolonlar temizlendi + referans kopyaları eklendi: 1) DefCollateralAnnex / DefCollateral Id'si → DefNumberGen YERİNE bigint IDENTITY. v3'te PrdProductDefinition'ı emsal almıştım; ölçüm o sayacın ÖLÜ olduğunu gösterdi (LastNumber 999 ama gerçek Id'ler 1..11; Create handler'da sayaç çağrıları yoruma alınmış). Sayaç deseni 2024-02'den sonra terk edilmiş; en yeni emsal AmortizationConfiguration (2026-04) bigint IDENTITY. DefNumberGen artık YALNIZ TxnCollateral için. 2) FlowEntity'nin 12. alanı PreviousActionId eklendi (koddan okundu; TxnTawarruq creation script'inde yoktu — script tek kaynak değil, base class asıl kaynak). 3) MakerCheckerEntity'nin CreatedBy/CreatedDate TANIMLAMADIĞI uyarısı eklendi (koddan: yalnız StateId/StateMaker/StateDate var). 4) YENİ SHEET 00_Referans_Kopyalari — her modül DB'si referans verisinin kendi kopyasını tutuyor (Common-MM kesişimi 44 tablo, Kafka ile beslenir). Collateral minimum +12 tablo / 13 topic / 12 handler → toplam 20 değil 32 tablo. 5) FAZLA KOLONLAR KALDIRILDI: 6 alt tabloda ValidFrom/ValidTo (parent revizyonu zaten geçerlilik penceresini taşıyor) · PaymentInstruction.ActiveFlow (TransactionType ile birebir tekrar) · TxnCollateral.BusinessKey (gerekçesizdi; Fimple/muhasebe faz-1 dışı). 6) Status (DRAFT/ACTIVE/INACTIVE) → IsEnabled bit. DRAFT≈StateId 16, ACTIVE≈StateId 18 olduğu için %70 tekrardı; INACTIVE'i MM'in standart IsEnabled deseni karşılıyor. | D8: Kullanıcı "gerçekten emin misin" diye sordu → 3 konu ölçümle kapatıldı. Ayrıca "AnnexProductScope'ta ValidFrom/ValidTo gerçekten gerekli mi" sorusu, dokümanın iki rakip versiyonlama desenini (immutable revizyon + effective-dated satır) üst üste taşıdığını ortaya çıkardı
A9: v5 | B9: 46301 | C9: Kimlik ve ilişki gösterimi tutarlılık düzeltmesi: • DefNumberGen yalnız TxnCollateral.Id için bırakıldı; diğer surrogate Id kolonları IDENTITY olarak kesinleştirildi. • 20 tablo sheet’ine açık PK/FK/UQ ve FK → hedef PK eşleşme kolonu eklendi. • Composite UQ alanları UQ1/UQ2/UQ3 grup etiketiyle gösterildi. • MarginRule UQ’dan kaldırılmış ValidFrom çıkarıldı. • v4’ten kalan Status ve ID üretimi çelişkileri temizlendi. | D9: Kullanıcı, güncel IDENTITY kararının tüm sheet’lerde uygulanmasını ve UML’deki açık anahtar eşleşmelerinin tablo sheet’lerinde de görünmesini istedi.

Sheet 00_Genel_Bakis
A1: Collateral Modülü — DB Şeması (v5)
A2: Kaynak: Hazine_Teminat_Yonetimi_Fonksiyonel_Teknik_Analiz v1.4 (30.09.2026) · Konvansiyon: NetTrexMM fiziksel şeması + .ai-agent/skills/db-script.md + Örnek_Scriptler/6-NetTrexMM-Tawarruq.sql emsali · Hedef DB: NetTrexCollateral (ad kesinleşmedi)
A4: Ekranlar
A5: # | B5: Ekran | C5: Açıklama | D5: İlişkili tablolar
A6: 1 | B6: Collateral Annex | C6: Sözleşmesel çerçeve. İçinde 2 popup: Add Product, Add Rule. | D6: DefCollateralAnnex, DefCollateralAnnexProductScope, DefCollateralAnnexMarginRule
A7: 2 | B7: Collateral Definition | C7: Cash veya Security varyantlı (CollateralType paneli seçer). | D7: DefCollateral + 6 alt tablo
A8: 3 | B8: Collateral Transaction | C8: Increase/Decrease + Limit Status + Near Payment Instructions. | D8: TxnCollateral, TxnCollateralCash, TxnCollateralSecurity, TxnCollateralLimit, TxnCollateralPaymentInstruction
A9: 4 | B9: Transaction Detail | C9: Kendi tablosu YOK — ledger'dan re-derive edilen salt-okunur tarihçe/running balance. | D9: (view/projection; TxnCollateralPosition hızlandırır)
A11: Tablolar — kategori ve Id stratejisi
A12: Tablo | B12: Kategori | C12: Id üretimi | D12: History + Trigger | E12: Not
A13: DefCollateralAnnex | B13: Maker-checker tanım (ekrandan düzenlenir) | C13: bigint IDENTITY | D13: ✅ gerekli | E13: 🔑 v4 DÜZELTMESİ: v3'te DefNumberGen demiştim, YANLIŞTI. Emsal aldığım PrdProductDefinition sayacı ÖLÜ (LastNumber 999, gerçek Id 1..11, Create handler'da sayaç çağrıları yoruma alınmış). Doğru emsal: AmortizationConfiguration (2026-04, bigint IDENTITY)
A14: DefCollateralAnnexProductScope | B14: Tanım alt tablosu | C14: bigint IDENTITY | D14: ❌ (saf eşleme — parent revizyonu kapsıyor) | E14: Add Product satırları. Emsal: PrdProductDefinitionMarketMap History almıyor
A15: DefCollateralAnnexMarginRule | B15: Tanım alt tablosu | C15: bigint IDENTITY | D15: ⚠️ TARTIŞMALI — parasal şart taşıyor | E15: Add Rule satırları (Threshold/MTA/Rounding). Emsal ayrımı: parasal/iş şartı taşıyan alt kayıt History ALIR (TxnCashFlow, AmortizationConfiguration); saf eşleme ALMAZ. Revizyon deseni sıkı uygulanırsa gerekmez
A16: DefCollateral | B16: Maker-checker tanım (ekrandan düzenlenir) | C16: bigint IDENTITY | D16: ✅ gerekli | E16: 🔑 v4 DÜZELTMESİ — yukarıdakiyle aynı gerekçe
A17: DefCollateralEligibleCurrency | B17: Tanım alt tablosu | C17: composite PK (Id yok) | D17: ❌ | E17: DefinitionId + CurrencyCode
A18: DefCollateralCashTerms | B18: Tanım alt tablosu (1:0..1) | C18: PK = FK (Id yok) | D18: ❌ | E18: DefinitionId paylaşımlı PK
A19: DefCollateralSettlementMap | B19: Tanım alt tablosu | C19: bigint IDENTITY | D19: ❌
A20: DefCollateralSecurityRule | B20: Tanım alt tablosu | C20: bigint IDENTITY | D20: ❌
A21: DefCollateralSecurityISIN | B21: Tanım alt tablosu | C21: composite PK (Id yok) | D21: ❌ | E21: DefinitionId + ISIN
A22: DefCollateralSecurityTerms | B22: Tanım alt tablosu (1:0..1) | C22: PK = FK (Id yok) | D22: ❌
A23: TxnCollateral | B23: 🔴 İşlem başlığı (flow) | C23: 🔴 DefNumberGen — IDENTITY DEĞİL | D23: ✅ ZORUNLU | E23: MM kuralı: Txn* tablosunda Id sayaçtan gelir (db-script.md §6)
A24: TxnCollateralCash | B24: İşlem alt tipi (1:1) | C24: PK = FK TxnId (Id yok) | D24: ❌ | E24: TxnMMDetail emsali — detayın History'si yok
A25: TxnCollateralSecurity | B25: İşlem alt tipi (1:1) | C25: PK = FK TxnId (Id yok) | D25: ❌
A26: TxnCollateralValuation | B26: Append-only snapshot | C26: bigint IDENTITY | D26: ❌ (zaten immutable) | E26: db-script.md: log/append-only tablo IDENTITY olur, DefNumberGen istemez
A27: TxnCollateralLimit | B27: Append-only snapshot | C27: bigint IDENTITY | D27: ❌
A28: TxnCollateralPaymentInstruction | B28: Versiyonlu talimat | C28: bigint IDENTITY | D28: ❌ | E28: Sürüm artışı yeni satır
A29: TxnCollateralMessage | B29: Mesaj başlığı | C29: bigint IDENTITY | D29: ❌
A30: TxnCollateralMessageEvent | B30: Append-only olay | C30: bigint IDENTITY | D30: ❌
A31: CollateralAuditLog | B31: Append-only log | C31: bigint IDENTITY | D31: ❌ | E31: ⚠️ MM'de polymorphic audit tablosu emsali YOK (bkz açık noktalar)
A32: TxnCollateralPosition | B32: 🔴 Bakiye projeksiyonu — ZORUNLU | C32: composite PK (Id yok) | D32: ❌ | E32: v2'de "opsiyonel" idi; eşzamanlı Decrease kontrolü için zorunlu oldu
A34: 🔴 Açık noktalar — karar bekliyor
A35: # | B35: Konu | C35: Durum
A36: 1 | B36: CollateralAuditLog deseni | C36: MM her tabloya `<Tablo>History` + trigger yazıyor, tek polymorphic audit tablosu kullanmıyor. Doküman tek tablo istiyor. İkisi birlikte de olabilir (History = satır bazlı, AuditLog = olay/korelasyon bazlı). Karar senin.
A37: 2 | B37: Status / LifecycleStatus ↔ StateId | C37: StateId maker-checker onay durumunu taşır. Annex/Definition için ayrı Status kaldırıldı; kullanılabilirlik `(StateId & 2) = 2 AND IsEnabled = 1` ile belirlenir. TxnCollateral.LifecycleStatus ise ekonomik/settlement yaşam döngüsü olarak ayrı kalır.
A38: 3 | B38: Fiziksel FK constraint | C38: MM emsal script’inde fiziksel FK sınırlıdır; ilişkiler Excel’de açık FK → hedef PK eşleşmesi ve EF modeli seviyesinde gösterilir. DDL’de fiziksel FK yazılıp yazılmayacağı ayrı karar olarak korunur.
A39: 4 | B39: DB adı | C39: `NetTrexCollateral` varsayıldı. Değişirse yalnız script'teki USE satırı değişir.
A40: 5 | B40: Security / SSI / Account / Rating master | C40: MM'de yok. Collateral'ın en büyük dış bağımlılığı — ayrı modül mü, Collateral içinde mi tanımlanacak (bkz 00_Iliskiler B).

Sheet 00_Tip_Kurallari
A1: Tip Kuralları (NetTrexMM fiziksel şemasından ölçüldü)
A2: Ofis standardı. Bu Excel'deki her kolon bu kurallara göre tiplenmiştir.
A4: Veri türü | B4: Tip | C4: Kural / gerekçe
A5: Primary key (Id) | B5: bigint | C5: 🔴 Ofis kuralı: tüm PK'ler long/bigint. MM'de eski tablolar int (TxnTawarruq.Id int) ama aktif migrasyon bigint yönünde — emsal: Örnek_Scriptler/4-NetTrexMM-TxnMmDailyCalculation-TxnMmId-long.sql
A6: Foreign key kolonu | B6: bigint (iç) / int (MM master) | C6: Collateral içi FK'ler bigint. MM'in mevcut master tablolarına (CusCustomer, PrfPortfolio, SettlementType) giden FK'ler o tablonun gerçek Id tipinde = int
A7: Para / tutar / değer | B7: decimal(38,10) | C7: MM fiziksel standardı (62 kolon). 🔴 decimal(38,2) MM'de FİZİKSEL OLARAK YOK. 2 ondalık kuralı DB'de değil validator'da
A8: Fiyat / nominal | B8: decimal(38,10) | C8: Tutarla aynı bucket
A9: FX kuru | B9: decimal(38,10) | C9: MM: FXRateDetail.*Rate, TxnSync.Rate = 38,10
A10: Oran / yüzde / haircut (0..1) | B10: decimal(18,10) | C10: MM: TaxRate.Rate, PremiumPercent, Spread = 18,10
A11: 🔴 float / double / real | B11: KULLANILMAZ | C11: Ofis kuralı: finansal hiçbir alanda float/double yok — yalnız decimal
A12: Boolean | B12: bit | C12: Kolon adı Is* (durum) veya Send*/Use* (eylem). NOT NULL + DEFAULT (0) tercih edilir
A13: İş tarihi (TradeDate, ValueDate, ValidFrom) | B13: date | C13: MM: 98 kolon date
A14: Zaman damgası / audit | B14: datetime | C14: MM: 117 kolon datetime. datetime2 yalnız HangFire'da. Kolon soneki ...Date (_at/Timestamp kalıbı YOK)
A15: Döviz kodu | B15: nvarchar(3) | C15: Ccy/CurrencyCode bucket'ı
... A21: Enum / sabit kod kümesi | B21: nvarchar(n) veya int | C21: MM ikisini de kullanıyor: lookup tablosu varsa <X>Id int FK, yoksa kısa kod nvarchar. Kolon yorumunda değer listesi yazılır (db-script.md §5)

Sheet 00_Sabitler
A1: Sabitler ve Kod Listeleri
A3: A) StateId bitmask — MM FlowState (tüm maker-checker tablolarında ortak)
A4: Değer | B4: Ad | C4: Anlamı
A5: 1 | B5: Rejected | C5: Reddedildi biti
A6: 2 | B6: Verified | C6: Onaylandı biti
A7: 4 | B7: Deleted | C7: Silindi biti
A8: 8 | B8: Edited | C8: Düzenlendi biti
A9: 16 | B9: Input | C9: Girildi biti
A10: 16 | B10: Input | C10: Girildi, onaysız
A11: 18 | B11: Input+Verified | C11: 🔑 Onaylı, aktif kayıt
A12: 17 | B12: Input+Rejected | C12: Reddedilmiş
A13: 20 | B13: Input+Deleted | C13: Silme talebi
A14: 22 | B14: Input+Verified+Deleted | C14: Onaylıydı, silindi
A15: 24 | B15: Input+Edited | C15: Düzenleme halinde
A16: 4112 | B16: (özel) WaitingApproval | C16: Tawarruq'ta çift-verify için açılmış özel state — Collateral çift verify isterse emsal bu
A18: B) FlowTransition ActionId değerleri (TxnTawarruq flow emsalinden)
A19: ActionId | B19: Eylem
A20: 2 | B20: Create (initial → Input)
A21: 4 | B21: Update
A22: 8 | B22: Delete
A23: 16 | B23: Verify
A24: 32 | B24: Reject
A26: C) Doküman kod listeleri — C# enum / nvarchar sabit değerleri
A27: Alan | B27: Değerler | C27: Kullanıldığı tablo(lar)
A28: Direction / EligibilityDirection | B28: BOTH · POST_ONLY · RECEIVE_ONLY | C28: DefCollateralAnnex, DefCollateral
A29: ~~Status~~ → IsEnabled bit | B29: 🔑 v4'te KALDIRILDI. DRAFT≈StateId 16 · ACTIVE≈StateId 18 (tekrar) · INACTIVE→ IsEnabled = 0 | C29: DefCollateralAnnex, DefCollateral
A30: CollateralType | B30: CASH · SECURITY | C30: DefCollateral, TxnCollateral
A31: MarginType | B31: VM · IM · IA · OTHER | C31: DefCollateralAnnexProductScope, TxnCollateral, TxnCollateralPosition
A32: Party | B32: OWN · COUNTERPARTY | C32: DefCollateralAnnexMarginRule
A33: RoundingMethod | B33: NEAREST · UP · DOWN | C33: DefCollateralAnnexMarginRule
A34: TransactionType | B34: INCREASE · DECREASE | C34: TxnCollateral, DefCollateralSettlementMap (v4: PaymentInstruction.ActiveFlow kaldırıldı, parent'tan okunur)
A35: LifecycleStatus | B35: DRAFT · VALIDATED · VERIFIED · MESSAGE_PENDING · MESSAGE_GENERATED · SENT · ACCEPTED · SETTLED · FAILED · CANCELLED · REVERSED | C35: TxnCollateral
A36: RateType | B36: FLOATING · FIXED · INTEREST_FREE | C36: DefCollateralCashTerms
A37: CompoundingMethod | B37: DAILY_COMPOUNDED · SIMPLE · NONE | C37: DefCollateralCashTerms
A38: DayCount | B38: ACT_360 · ACT_365 · THIRTY_360 | C38: DefCollateralCashTerms
... A56: Channel (audit) | B56: UI · API · BATCH · ADAPTER | C56: CollateralAuditLog
A58: D) FrameworkParameter satırları (NetTrexCommon — sp_FrameworkAddParameter ile)
A59: OptionPath | B59: OptionName | C59: Örnek değer | D59: Ne işe yarar
A60: Collateral | B60: Module.IsEnabled | C60: true | D60: Modül kill-switch (MM'in InterbankLoan:Enabled emsali)
A61: Collateral | B61: DefaultPortfolioPath | C61: 0/1/2/0/176/ | D61: 🔑 Portföy parametresi Code değil PATH taşır (PrfPortfolio.Code tekil değil)
...

Sheet 00_DB_Nesneleri
A1: Tablo Dışında Üretilmesi Gereken DB Nesneleri
A2: Kaynak: .ai-agent/skills/db-script.md + NetTrex.MM/.ai-agent/imports/Örnek_Scriptler/ (Tawarruq emsali). Script üretilirken bu liste eksiksiz uygulanır.
A4: # | B4: Nesne | C4: Hangi DB | D4: Hangi tablolar için | E4: Kalıp / örnek
A5: 1 | B5: History tablosu | C5: NetTrexCollateral | D5: DefCollateralAnnex, DefCollateral, TxnCollateral (maker-checker/StateId taşıyan 3 tablo) | E5: `<Tablo>History`: [HistoryId] bigint IDENTITY(1,1) PK + ana tablonun TÜM kolonları AYNI SIRADA. PK adı: PK_<Tablo>History
A6: 2 | B6: Trigger | C6: NetTrexCollateral | D6: Yukarıdaki 3 tablo | E6: 🔑 `CREATE OR ALTER TRIGGER [dbo].[<Tablo>Trigger] ON [dbo].[<Tablo>] FOR INSERT, UPDATE AS BEGIN SET NOCOUNT ON; INSERT INTO [dbo].[<Tablo>History] ([Kolon1],[Kolon2],…) SELECT [Kolon1],[Kolon2],… FROM inserted; END` — 🔴 **AÇIK KOLON LİSTESİ** kullan (TxnMMTrigger kalıbı). `SELECT * FROM inserted` eski kuşak (PrdProductDefinitionTrigger) ve kolon sırasına bağımlı — kullanma. Trigger batch'in İLK satırı olmalı
A7: 3 | B7: DefNumberGen satırı | C7: NetTrexCollateral | D7: Yalnız TxnCollateral | E7: DefNumberGen yalnız TxnCollateral.Id için açılır: Definition = 'Txn Collateral Id'. DefCollateralAnnex.Id ve DefCollateral.Id dahil diğer surrogate Id kolonları bigint IDENTITY(1,1); composite ve PK=FK tablolarda ayrı Id yoktur.
A8: 4 | B8: DefRefNumGen / LogicalReference tipi | C8: NetTrexCollateral | D8: TxnCollateral | E8: LogicalReference üretimi ayrı sayaç (sp_GetNewRefNumber, günlük sıfırlanır). LogicalReferenceType satırı + prefix (ör. TCL) tanımlanmalı
A9: 5 | B9: FlowState / FlowSet / FlowRequestMap / FlowTransition | C9: NetTrexCollateral | D9: TxnCollateral (maker-checker akışı) | E9: Emsal: Örnek_Scriptler/6-NetTrexMM-Tawarruq.sql satır 432-594. FlowSet (ör. "CollateralTransactionFlow") + 15-17 FlowTransition satırı (Input 16 → Verify 18 → Delete 20/22 → Edit 24). Çift verify istenirse ek FlowState + FlowDynamicRule
A10: 6 | B10: DefCountMonitoring satırı | C10: 🔴 NetTrexCommon | D10: 🔑 TABLO başına değil, EKRAN başına (en çok 3) | E10: Ölçüldü (30 satır var): Id = MAX(Id)+1 (IDENTITY DEĞİL) · ScreenName nvarchar(100) ör. 'Collateral Transactions' · Query = 'EXEC sp_UnverifiedDataCount_<Ekran> @CurrentUserId' · ScreenUrl = 'general/<Controller>/Index' · Connection = 'Connection' (literal) · DefaultUnverifiedStateId = '3' (nvarchar) · State = 1 (0 = kapalı)
A11: 7 | B11: sp_UnverifiedDataCount_<Ekran> | C11: 🔴 NetTrexCommon | D11: 🔑 EKRAN başına 1 adet (tablo başına DEĞİL) | E11: Ölçüldü: Common'da 30 adet var, modül DB'lerinde YOK. EXEC('CREATE PROCEDURE …') ile kurulur (GO sorunu). Gövde: `SELECT @HavePermission = dbo.fn_HasPermissionWithUserId(@CurrentUserId, '<Ekran>\_%')` + cross-DB sayım `FROM NetTrexCollateral.dbo.<Tablo> WITH (NOLOCK) WHERE (StateId & 2) <> 2 AND (StateId & 1) <> 1` · yetkisizse -1 döner
A12: 7b | B12: 🚫 Modül DB'sine SP YAZMA | C12: NetTrexCollateral | D12: — | E12: Ölçüldü: NetTrexMM'de 125 tabloya karşılık yalnız 9 SP var ve hiçbiri 'her tablo için açılan' türden değil (2'si sayaç, kalanı legacy entegrasyon/rapor). 🔑 Yeni tablo açmak SP açmayı GEREKTİRMEZ. İş mantığı C# handler/DataManager'da
A13: 7c | B13: 🚫 Function YAZMA | C13: NetTrexCollateral | D13: — | E13: Ölçüldü: 28 scalar + 1 TVF var, hepsi 2020-2025 legacy finans kütüphanesi (fn_Accrual, fd_LgDt, fn_ConvertCCY…), modül başına üretilmiyor. Gerekirse MEVCUT fonksiyonları çağır, yenisini yazma
A14: 8 | B14: FrameworkParameter satırları | C14: 🔴 NetTrexCommon | D14: — | E14: exec [dbo].[sp_FrameworkAddParameter] '<Path>','<Name>','<Value>' — elle INSERT YASAK. Liste: 00_Sabitler D bölümü
A15: 9 | B15: FrameworkMenu satırları | C15: 🔴 NetTrexCommon | D15: 3 ekran | E15: MenuKey ile IF NOT EXISTS. 🔴 Menü Redis'te ModuleMenu:{UserId} altında 8 saat cache'li — script sonrası flush notu şart
A16: 10 | B16: Permission (sp_FrameworkAddPermission) | C16: NetTrexCommon | D16: 🔴 YALNIZ Trex.WebUI ekranı yapılırsa | E16: Collateral Micro UI olarak yapılacaksa permission satırı YAZILMAZ (db-script.md §4). Micro UI'da erişim menü üzerinden
A17: 11 | B17: Index'ler | C17: NetTrexCollateral | D17: Tümü | E17: Bkz 00_Constraint_Index sheet'i
A18: 12 | B18: Bakiye güncelleme (TxnCollateralPosition) | C18: NetTrexCollateral | D18: TxnCollateral Verify akışı | E18: 🔴 Eşzamanlı Decrease'i önlemek için: pozisyon satırı Verify ile AYNI transaction içinde `WITH (UPDLOCK, ROWLOCK)` ile okunup güncellenir — DefNumberGen'in sp_GetNewNumbers'da kullandığı kanıtlanmış kalıbın aynısı

Sheet 00_Constraint_Index
A1: Constraint ve Index Listesi (ev isimlendirmesiyle)
A2: İsim kalıpları (db-script.md §5): PK_<Tablo> · UQ_<Tablo>_<Kolon> · IX_<Tablo>_<Kolon> · DF_<Tablo>_<Kolon> · <Tablo>Trigger. FK kalıbı: FK_<Tablo>_<HedefTablo>_<Kolon> (EF default) — ⚠️ MM emsal script'inde fiziksel FK YAZILMIYOR, karar 00_Genel_Bakis açık nokta #3.
A4: A) Primary key
A5: Tablo | B5: Constraint adı | C5: Kolon(lar) | D5: Not
A6: DefCollateralAnnex | B6: PK_DefCollateralAnnex | C6: Id | D6: CLUSTERED
A7: DefCollateralAnnexProductScope | B7: PK_DefCollateralAnnexProductScope | C7: Id
A8: DefCollateralAnnexMarginRule | B8: PK_DefCollateralAnnexMarginRule | C8: Id
A9: DefCollateral | B9: PK_DefCollateral | C9: Id
A10: DefCollateralEligibleCurrency | B10: PK_DefCollateralEligibleCurrency | C10: DefinitionId, CurrencyCode | D10: Composite — aynı para birimi tekrar edemez
A11: DefCollateralCashTerms | B11: PK_DefCollateralCashTerms | C11: DefinitionId | D11: PK = FK (1:0..1)
A12: DefCollateralSettlementMap | B12: PK_DefCollateralSettlementMap | C12: Id
A13: DefCollateralSecurityRule | B13: PK_DefCollateralSecurityRule | C13: Id
A14: DefCollateralSecurityISIN | B14: PK_DefCollateralSecurityISIN | C14: DefinitionId, ISIN | D14: Composite
A15: DefCollateralSecurityTerms | B15: PK_DefCollateralSecurityTerms | C15: DefinitionId | D15: PK = FK
A16: TxnCollateral | B16: PK_TxnCollateral | C16: Id | D16: CLUSTERED · Id DefNumberGen'den
A17: TxnCollateralCash | B17: PK_TxnCollateralCash | C17: TxnId | D17: PK = FK
A18: TxnCollateralSecurity | B18: PK_TxnCollateralSecurity | C18: TxnId | D18: PK = FK
A19: TxnCollateralValuation | B19: PK_TxnCollateralValuation | C19: Id
A20: TxnCollateralLimit | B20: PK_TxnCollateralLimit | C20: Id
A21: TxnCollateralPaymentInstruction | B21: PK_TxnCollateralPaymentInstruction | C21: Id
A22: TxnCollateralMessage | B22: PK_TxnCollateralMessage | C22: Id
A23: TxnCollateralMessageEvent | B23: PK_TxnCollateralMessageEvent | C23: Id
A24: CollateralAuditLog | B24: PK_CollateralAuditLog | C24: Id
A25: TxnCollateralPosition | B25: PK_TxnCollateralPosition | C25: DefinitionId, MarginType, AssetCode | D25: Composite — bakiye kırılımının kendisi
A26: <Tablo>History (3 adet) | B26: PK_<Tablo>History | C26: HistoryId | D26: bigint IDENTITY
A28: B) Unique index — iş kuralı taşıyanlar 🔴 (ad kalıbı: UQ_<Tablo>_<İlkKolon> — MM'de composite UQ adı YALNIZ ilk kolonu taşıyor, ölçüldü: UQ_FXRateDetail_FXRateId 3 kolonluk)
A29: Index adı | B29: Tablo (kolonlar) | C29: Hangi iş kuralını/kabul kriterini karşılıyor
A30: UQ_DefCollateralAnnex_AnnexCode | B30: DefCollateralAnnex (AnnexCode, RevisionNo) | C30: AC-37 — aynı iş kodunda revizyon tekilliği
A31: UQ_DefCollateral_CollateralCode | B31: DefCollateral (CollateralCode, RevisionNo) | C31: AC-37 — aynı Collateral Code'da revizyon tekilliği
A32: UQ_TxnCollateral_TransactionReference | B32: TxnCollateral (TransactionReference) | C32: İşlem referansı tekilliği
A33: UQ_TxnCollateral_LogicalReference | B33: TxnCollateral (LogicalReference) | C33: ✅ MM emsali birebir: UQ_TxnMM_LogicalReference, UQ_TxnTawarruq_LogicalReference
A34: UQ_TxnCollateral_SourceSystem | B34: TxnCollateral (SourceSystem, ExternalReference) | C34: 🔴 AC-35 — harici kaynak duplicate engeli. ⚠️ MM'de FILTERED index HİÇ YOK (5/5 filtered değil). İki seçenek: (a) bilinçli sapma → WHERE ExternalReference IS NOT NULL filtered index, (b) ev deseni → kolonları NOT NULL DEFAULT('') yapıp düz UQ. 🔑 Karar gerekiyor
A35: UQ_TxnCollateralLimit_TxnId | B35: TxnCollateralLimit (TxnId, SnapshotStage) | C35: Aynı aşama için duplicate limit snapshot engeli
A36: UQ_TxnCollateralPaymentInstruction_TxnId | B36: TxnCollateralPaymentInstruction (TxnId, InstructionVersion) | C36: Talimat sürüm tekilliği
A37: UQ_TxnCollateralMessage_IdempotencyKey | B37: TxnCollateralMessage (IdempotencyKey) | C37: 🔴 AC-12/AC-17 — duplicate ödeme/settlement mesajı engeli
A38: UQ_TxnCollateralMessage_UETR | B38: TxnCollateralMessage (UETR) | C38: ⚠️ UETR nullable → ya filtered index (ev deseninden sapma) ya da unique'ten vazgeçip IX kullan
A39: UQ_DefCollateralAnnexMarginRule_ProductScopeId | B39: DefCollateralAnnexMarginRule (ProductScopeId, Party, CurrencyCode) | C39: Aynı ürün kapsamı + taraf + para birimi için duplicate kuralı önler; geçerlilik parent Annex revizyonundan gelir.
A41: C) Non-unique index — performans
A42: Index adı | B42: Tablo (kolonlar) | C42: Neden
A43: IX_TxnCollateral_DefinitionId_ValueDate | B43: TxnCollateral (DefinitionId, ValueDate) | C43: Tarihçe + running balance sorgusu (doküman §10.23)
...

Sheet 00_Referans_Kopyalari
A1: Referans Veri Kopyaları — NetTrexCollateral'de AÇILMASI ZORUNLU Tablolar
A2: 🔴 ÖLÇÜLDÜ: NetTrexCommon master, her modül DB'si referans verisinin KENDİ kopyasını tutuyor (Common↔MM kesişimi 44 tablo) ve Kafka ile besleniyor. Her modül YALNIZ ihtiyacı kadarını açıyor (MM 24 topic, OptionsFX 11). Kanıt: Tawarruq script'i aynı kolonu 5 ayrı DB'nin CusCustomer'ına ekliyor.
A4: 🔴 3 ZORUNLU KURAL (kopya tablolar normal tablolardan FARKLI davranır)
A5: Kural | B5: Gerekçe
A6: Id IDENTITY DEĞİL — EF config'te `.ValueGeneratedNever()` açıkça yazılır | B6: Common'ın Id'si birebir taşınıyor. Emsal: PortfolioConfiguration, MarketCustomerMapConfiguration
A7: DefNumberGen sayacı AÇILMAZ | B7: Id dışarıdan geliyor, üretilmiyor
A8: History + Trigger YAZILMAZ | B8: Tarihçe Common'da (CustomerHistory vb.). MM'in 9 History tablosunun hiçbiri referans kopyası değil
A10: KATMAN A — çekirdek, tartışmasız (12 tablo · 13 topic · 12 handler)
A11: Tablo (NetTrexCollateral) | B11: Common'daki adı | C11: Kafka topic | D11: Handler | E11: Collateral neden ihtiyaç duyuyor
A12: CusCustomer | B12: Customer | C12: customer-insert | D12: CustomerCreateHandler | E12: Counterparty — Annex/Definition/Transaction'ın hepsinde FK
A13: PrfPortfolio | B13: Portfolio | C13: portfolio-insert | D13: PortfolioCreateHandler | E13: TxnCollateral.PortfolioId
A14: Currency | B14: Currency | C14: currency-insert | D14: CurrencyCreateHandler | E14: Her tutar/değerleme kolonunun para birimi
A15: DefDateBasis | B15: DateBasis | C15: datebasis-insert | D15: DateBasisCreateHandler | E15: Cash faiz şartları (DayCount)
A16: Calendar | B16: Calendar | C16: calendar-insert + calendar-delete | D16: CalendarCreateHandler + CalendarDeleteHandler | E16: ValueDate/BusinessDayRule hesabı
A17: Holiday | B17: Holiday | C17: holiday-insert + holiday-delete | D17: HolidayCreateHandler + HolidayDeleteHandler | E17: Tatil kaydırma (AC-36 cut-off)
A18: HalfWorkingDay | B18: HalfWorkingDay | C18: halfworkingday-insert | D18: CreateHalfWorkingDayHandler | E18: Yarım gün takvimi
A19: DefCountry | B19: Country | C19: country-insert | D19: CreateCountryHandler | E19: DefCollateralSecurityRule.CountryOfRiskCode
A20: DefCorporateType + DefCorporateDetailType | B20: CorporateType | C20: corporate-type-insert | D20: CreateCorporateTypeHandler ⚠️ TEK handler → İKİ tablo | E20: Karşı taraf tüzel kişilik tipi
A21: FXRate + FXRateDetail | B21: FXRate(Detail) | C21: fxrate-insert, fxratedetail-insert, fxratedetail-delete | D21: FxRateInsertHandler, FxRateDetailInsertHandler, FxRateDetailDeleteHandler | E21: 🔑 FX dönüşümü + haircut hesabının temeli (doküman §8.1)
A23: KATMAN B / C / D — koşullu
A24: Katman | B24: Tablolar | C24: Koşul
A25: B (+2) | B25: ExternalCustomerMap, ExternalUserMap | C25: Collateral Fimple/muhasebe entegrasyonuna girerse. Faz-1'de muhasebe KAPSAM DIŞI (doküman §1.1) → muhtemelen gerekmez
A26: C (+5) | B26: InterestRate + InterestRateDetail · Chart + Point · Market + MarketCustomerMap + DefTxnType | C26: ⚠️ TAHMİN: NPV/iskonto hesabı veya eğri/fiyat verisi gerekirse. Collateral değerlemesi fiyat × nominal × haircut olduğu için muhtemelen GEREKMİYOR
A27: D — AÇMA | B27: TaxTax/TaxRate/TaxRule/TaxType · DefBitMask · CusSIC · Branch · CurrencyPair · DefTaxOffice · DefLegalVehicle · UsrUserLayout … | C27: 🔴 MM'de Tax topic'leri KAPALI (TaxRule tablosu 0 satır), diğerlerinin Consumer'ı hiç yok — seed/legacy taşıma
A29: Tablo sayısına etkisi
A30: Senaryo | B30: Referans kopyası | C30: Handler | D30: Topic | E30: Collateral toplam tablo
A31: Katman A (önerilen) | B31: +12 | C31: 12 | D31: 13 | E31: 20 iş tablosu + 12 = **32**
A32: A + B (Fimple'lı) | B32: +14 | C32: 14 | D32: 15 | E32: 34
A33: Tam MM paritesi | B33: +19 | C33: 20 | D33: 24 | E33: 39
A35: ⚠️ MM'in yapmadığı, Collateral'ın yapabileceği iyileştirme
A36: Sorun (MM'de ölçüldü) | B36: Öneri
A37: Consumer handler'ları doğrulama YAPMIYOR — exists-check → insert/update, o kadar. Bedeli ölçülmüş veri kalitesi sorunları: Currency.IsoCode tutarsız · Currency.BasisCode='SPOT' (DefDateBasis'te böyle bir değer yok) · CusCustomer.ExternalCustomerId mükerrer | B37: Collateral consumer'ına basit bir doğrulama katmanı ekle (zorunlu alan + FK varlık kontrolü + log). MM'in yapmadığı bir iyileştirme olur
A38: Topic adları appsettings'te değil, RequestCreatorFactory.cs içinde hardcode dictionary; her anahtar için ayrı Thread | B38: Aynı deseni kopyala (tutarlılık için) ama topic listesini sabit sınıfa almayı değerlendir

Sheet 00_Iliskiler
A1: Tablolar Arası İlişkiler (FK → PK)
A2: 🔴 ÖLÇÜLDÜ: NetTrexMM'de 125 tabloya karşılık yalnız 14 fiziksel FK var (hepsi referans/tanım tablolarına, hepsi NO_ACTION) — işlem/detay/history tabloları arasında FK YOK, son 2 yılın hiçbir script'inde FOREIGN KEY geçmiyor. İlişkiler EF model tarafında (HasOne/WithMany) tanımlı. Aşağıdaki FK adları, yazılmasına karar verilirse kullanılacak ev kalıbıdır: FK_<BağımlıTablo>_<HedefTablo>_<FkKolonu> (EF default, 14/14 uyuyor) · ON DELETE yazma (NO_ACTION default) · CASCADE ev deseninde YOK.
A4: A) İç ilişkiler — Collateral'ın kendi tabloları
A5: Parent Tablo | B5: Parent PK | C5: Child Tablo | D5: Child FK Kolonu | E5: FK Constraint adı (yazılırsa) | F5: Kardinalite / not
A6: DefCollateralAnnex | B6: Id | C6: DefCollateralAnnexProductScope | D6: AnnexId | E6: FK_DefCollateralAnnexProductScope_DefCollateralAnnex_AnnexId | F6: 1:N · ON DELETE NO ACTION
A7: DefCollateralAnnexProductScope | B7: Id | C7: DefCollateralAnnexMarginRule | D7: ProductScopeId | E7: FK_DefCollateralAnnexMarginRule_DefCollateralAnnexProductScope_ProductScopeId | F7: 1:N
A8: DefCollateralAnnex | B8: Id | C8: DefCollateral | D8: AnnexId | E8: FK_DefCollateral_DefCollateralAnnex_AnnexId | F8: 1:N opsiyonel (nullable — standalone definition)
A9: DefCollateral | B9: Id | C9: DefCollateralEligibleCurrency | D9: DefinitionId | E9: FK_DefCollateralEligibleCurrency_DefCollateral_DefinitionId | F9: 1:N · Cash için en az 1 aktif satır
A10: DefCollateral | B10: Id | C10: DefCollateralCashTerms | D10: DefinitionId | E10: FK_DefCollateralCashTerms_DefCollateral_DefinitionId | F10: 1:0..1 · yalnız CASH
A11: DefCollateral | B11: Id | C11: DefCollateralSecurityRule | D11: DefinitionId | E11: FK_DefCollateralSecurityRule_DefCollateral_DefinitionId | F11: 1:N · Security Scope = Rule
A12: DefCollateral | B12: Id | C12: DefCollateralSecurityISIN | D12: DefinitionId | E12: FK_DefCollateralSecurityISIN_DefCollateral_DefinitionId | F12: 1:N · Security Scope = Specific ISIN
A13: DefCollateral | B13: Id | C13: DefCollateralSecurityTerms | D13: DefinitionId | E13: FK_DefCollateralSecurityTerms_DefCollateral_DefinitionId | F13: 1:0..1 · yalnız SECURITY
A14: DefCollateral | B14: Id | C14: DefCollateralSettlementMap | D14: DefinitionId | E14: FK_DefCollateralSettlementMap_DefCollateral_DefinitionId | F14: 1:N
A15: DefCollateral | B15: Id | C15: TxnCollateral | D15: DefinitionId | E15: FK_TxnCollateral_DefCollateral_DefinitionId | F15: 1:N · 🔴 işlem varken definition silinemez
A16: DefCollateralAnnex | B16: Id | C16: TxnCollateral | D16: AnnexId | E16: FK_TxnCollateral_DefCollateralAnnex_AnnexId | F16: 1:N opsiyonel
... A27: (polymorphic) | B27: — | C27: CollateralAuditLog | D27: AggregateId + AggregateType | E27: ❌ FK yazılamaz | F27: Polymorphic — gerçek FK constraint mümkün değil
A28: B) Dış bağımlılıklar — mevcut MM tabloları vs yeni gerekenler
A29: Kolon(lar) | B29: Hedef | C29: Durum | D29: Not
A30: CustomerId (4 tabloda) | B30: CusCustomer.Id | C30: ✅ MM'de VAR | D30: Counterparty = MM'in Customer kavramı. Tip: int (MM'in mevcut tipi)
A31: CurrencyCode (çok sayıda) | B31: Currency | C31: ✅ MM'de VAR | D31: nvarchar(3) doğal anahtar
A32: PortfolioId | B32: PrfPortfolio.Id | C32: ✅ MM'de VAR | D32: 🔑 Varsayılan portföy parametreden PATH ile çözülür, Code ile değil
A33: SettlementTypeId | B33: SettlementType.Id | C33: ✅ MM'de VAR | D33: Değer kümesi örtüşüyor (Gross/Netting) — yeni tablo AÇMA
A34: PaymentInstructionTypeId | B34: PaymentInstructionType.Id | C34: ✅ MM'de VAR | D34: B2B/A2A/Vostro/A2AD — yeni tablo AÇMA
A35: TraderUserId / StateMaker / CreatedBy | B35: Kullanıcı (nvarchar(80)) | C35: ✅ MM deseni | D35: MM ayrı User tablosuna FK vermiyor, string tutuyor
A36: ProductCode, SubProductCode | B36: Ürün kataloğu | C36: ⚠️ NETLEŞMEDİ | D36: MM'in PrdProductDefinition'ı hazine ürün ailesi (FX/IR/Repo) için yeterli mi?
A37: SettlementAccountId, InterestAccountId | B37: Hesap master | C37: ⚠️ NETLEŞMEDİ | D37: MM'de hesap Fimple'dan geliyor (AccountNumber/GLCode kolonları), ayrı master yok
A38: SsiId (5 kolonda) | B38: SSI master | C38: 🔴 YENİ GEREKLİ | D38: MM'de yok. Collateral içinde mi, ortak modülde mi?
A39: ISIN, SecurityTypeCode, IssuerTypeCode, MinimumRatingCode | B39: Menkul kıymet master | C39: 🔴 YENİ GEREKLİ | D39: Collateral'ın en büyük dış bağımlılığı
A40: SettlementLocationCode | B40: CSD/ICSD kataloğu | C40: 🔴 YENİ GEREKLİ | D40: Takasbank/Euroclear/Clearstream
... A43: CountryOfRiskCode | B43: Ülke kataloğu | C43: ⚠️ MM'de DefCountry var | D43: Kontrol edilmeli

Sheet 00_UML_Diyagram
B1: Collateral DB — UML / ER Diyagramı (canlı: kolonlar tablo sheet'lerinden formülle okunur)
B3: Renk: | C3: Annex grubu | D3: Definition grubu | E3: Txn grubu | F3: Log / polymorphic
AA5: İlişki listesi (canlı — 00_Iliskiler bölüm A'dan okunur) | AF5: Görsel bağlantı anahtarı — FK → PK
B6: =DefCollateralAnnexProductScope!A1 -> DefCollateralAnnexProductScope | G6: =DefCollateralAnnex!A1 -> DefCollateralAnnex | Q6: =TxnCollateralCash!A1 -> TxnCollateralCash | V6: =CollateralAuditLog!A1 -> CollateralAuditLog | AA6: {=_xlfn.LET(_xlpm.d,'00_Iliskiler'!$A$5:$F$60,_xlpm.k,INDEX(_xlpm.d,,1),_xlpm.e,MATCH(TRUE,_xlpm.k="",0)-1,_xlfn.TAKE(_xlfn.CHOOSECOLS(_xlpm.d,1,2,3,4,6),_xlpm.e))} -> Parent Tablo | AB6: Parent PK | AC6: Child Tablo | AD6: Child FK Kolonu | AE6: Kardinalite / not | AF6: Bağlantı | AG6: Açık kolon eşleşmesi (Child.FK → Parent.PK)
B7: Anahtar | C7: ="Kolon / FK hedefi ("&ROWS(_xlfn.ANCHORARRAY(B8))&")" -> Kolon / FK hedefi (6) | D7: Tip | E7: Null | G7: Anahtar | H7: ="Kolon / FK hedefi ("&ROWS(_xlfn.ANCHORARRAY(G8))&")" -> Kolon / FK hedefi (19) | I7: Tip | J7: Null | Q7: Anahtar | R7: ="Kolon / FK hedefi ("&ROWS(_xlfn.ANCHORARRAY(Q8))&")" -> Kolon / FK hedefi (10) | S7: Tip | T7: Null | V7: Anahtar | W7: ="Kolon / FK hedefi ("&ROWS(_xlfn.ANCHORARRAY(V8))&")" -> Kolon / FK hedefi (11) | X7: Tip | Y7: Null | AA7: DefCollateralAnnex | AB7: Id | AC7: DefCollateralAnnexProductScope | AD7: AnnexId | AE7: 1:N · ON DELETE NO ACTION | AF7: R01 | AG7: =IF($AF7="POLY",$AC7&".["&$AD7&"] → polymorphic (fiziksel FK yok)",$AC7&"."&$AD7&" → "&$AA7&"."&$AB7) -> DefCollateralAnnexProductScope.AnnexId → DefCollateralAnnex.Id
B8: {=_xlfn.LET(_xlpm.d,DefCollateralAnnexProductScope!$A$7:$F$79,_xlpm.n,INDEX(_xlpm.d,,1),_xlpm.t,INDEX(_xlpm.d,,2),_xlpm.nl,INDEX(_xlpm.d,,3),_xlpm.c,INDEX(_xlpm.d,,5),_xlpm.f,INDEX(_xlpm.d,,6),_xlpm.pk,ISNUMBER(SEARCH("PK_",_xlpm.c))+ISNUMBER(SEARCH("(PK ile)",_xlpm.c)),_xlpm.fk,(LEFT(_xlpm.f,3)="Def")+(LEFT(_xlpm.f,3)="Txn"),_xlpm.qone,ISNUMBER(SEARCH("UQ1",_xlpm.c)),_xlpm.qtwo,ISNUMBER(SEARCH("UQ2",_xlpm.c)),_xlpm.qthree,ISNUMBER(SEARCH("UQ3",_xlpm.c)),_xlpm.uq,ISNUMBER(SEARCH("UQ",_xlpm.c)),_xlpm.ul,IF(_xlpm.qone,"UQ1",IF(_xlpm.qtwo,"UQ2",IF(_xlpm.qthree,"UQ3","UQ"))),_xlpm.ky,TRIM(IF(_xlpm.pk,"PK ","")&IF(_xlpm.fk,"FK ","")&IF(_xlpm.uq*(_xlpm.pk=0),_xlpm.ul,"")),_xlfn._xlws.FILTER(CHOOSE({1,2,3,4},_xlpm.ky,IF(_xlpm.fk,_xlpm.n&" → "&_xlpm.f,_xlpm.n),_xlpm.t,IF(_xlpm.nl="Yes","NULL","NOT NULL")),(_xlpm.n<>"")*(LEFT(_xlpm.n,1)<>"—")))} -> PK | C8: Id | D8: bigint | E8: NOT NULL | G8: {=_xlfn.LET(_xlpm.d,DefCollateralAnnex!$A$7:$F$80,_xlpm.n,INDEX(_xlpm.d,,1),_xlpm.t,INDEX(_xlpm.d,,2),_xlpm.nl,INDEX(_xlpm.d,,3),_xlpm.c,INDEX(_xlpm.d,,5),_xlpm.f,INDEX(_xlpm.d,,6),_xlpm.pk,ISNUMBER(SEARCH("PK_",_xlpm.c))+ISNUMBER(SEARCH("(PK ile)",_xlpm.c)),_xlpm.fk,(LEFT(_xlpm.f,3)="Def")+(LEFT(_xlpm.f,3)="Txn"),_xlpm.qone,ISNUMBER(SEARCH("UQ1",_xlpm.c)),_xlpm.qtwo,ISNUMBER(SEARCH("UQ2",_xlpm.c)),_xlpm.qthree,ISNUMBER(SEARCH("UQ3",_xlpm.c)),_xlpm.uq,ISNUMBER(SEARCH("UQ",_xlpm.c)),_xlpm.ul,IF(_xlpm.qone,"UQ1",IF(_xlpm.qtwo,"UQ2",IF(_xlpm.qthree,"UQ3","UQ"))),_xlpm.ky,TRIM(IF(_xlpm.pk,"PK ","")&IF(_xlpm.fk,"FK ","")&IF(_xlpm.uq*(_xlpm.pk=0),_xlpm.ul,"")),_xlfn._xlws.FILTER(CHOOSE({1,2,3,4},_xlpm.ky,IF(_xlpm.fk,_xlpm.n&" → "&_xlpm.f,_xlpm.n),_xlpm.t,IF(_xlpm.nl="Yes","NULL","NOT NULL")),(_xlpm.n<>"")*(LEFT(_xlpm.n,1)<>"—")))} -> PK | H8: Id | I8: bigint | J8: NOT NULL | Q8: {=_xlfn.LET(_xlpm.d,TxnCollateralCash!$A$7:$F$80,_xlpm.n,INDEX(_xlpm.d,,1),_xlpm.t,INDEX(_xlpm.d,,2),_xlpm.nl,INDEX(_xlpm.d,,3),_xlpm.c,INDEX(_xlpm.d,,5),_xlpm.f,INDEX(_xlpm.d,,6),_xlpm.pk,ISNUMBER(SEARCH("PK_",_xlpm.c))+ISNUMBER(SEARCH("(PK ile)",_xlpm.c)),_xlpm.fk,(LEFT(_xlpm.f,3)="Def")+(LEFT(_xlpm.f,3)="Txn"),_xlpm.qone,ISNUMBER(SEARCH("UQ1",_xlpm.c)),_xlpm.qtwo,ISNUMBER(SEARCH("UQ2",_xlpm.c)),_xlpm.qthree,ISNUMBER(SEARCH("UQ3",_xlpm.c)),_xlpm.uq,ISNUMBER(SEARCH("UQ",_xlpm.c)),_xlpm.ul,IF(_xlpm.qone,"UQ1",IF(_xlpm.qtwo,"UQ2",IF(_xlpm.qthree,"UQ3","UQ"))),_xlpm.ky,TRIM(IF(_xlpm.pk,"PK ","")&IF(_xlpm.fk,"FK ","")&IF(_xlpm.uq*(_xlpm.pk=0),_xlpm.ul,"")),_xlfn._xlws.FILTER(CHOOSE({1,2,3,4},_xlpm.ky,IF(_xlpm.fk,_xlpm.n&" → "&_xlpm.f,_xlpm.n),_xlpm.t,IF(_xlpm.nl="Yes","NULL","NOT NULL")),(_xlpm.n<>"")*(LEFT(_xlpm.n,1)<>"—")))} -> PK FK | R8: TxnId → TxnCollateral.Id | S8: bigint | T8: NOT NULL | V8: {=_xlfn.LET(_xlpm.d,CollateralAuditLog!$A$7:$F$80,_xlpm.n,INDEX(_xlpm.d,,1),_xlpm.t,INDEX(_xlpm.d,,2),_xlpm.nl,INDEX(_xlpm.d,,3),_xlpm.c,INDEX(_xlpm.d,,5),_xlpm.f,INDEX(_xlpm.d,,6),_xlpm.pk,ISNUMBER(SEARCH("PK_",_xlpm.c))+ISNUMBER(SEARCH("(PK ile)",_xlpm.c)),_xlpm.fk,(LEFT(_xlpm.f,3)="Def")+(LEFT(_xlpm.f,3)="Txn"),_xlpm.qone,ISNUMBER(SEARCH("UQ1",_xlpm.c)),_xlpm.qtwo,ISNUMBER(SEARCH("UQ2",_xlpm.c)),_xlpm.qthree,ISNUMBER(SEARCH("UQ3",_xlpm.c)),_xlpm.uq,ISNUMBER(SEARCH("UQ",_xlpm.c)),_xlpm.ul,IF(_xlpm.qone,"UQ1",IF(_xlpm.qtwo,"UQ2",IF(_xlpm.qthree,"UQ3","UQ"))),_xlpm.ky,TRIM(IF(_xlpm.pk,"PK ","")&IF(_xlpm.fk,"FK ","")&IF(_xlpm.uq*(_xlpm.pk=0),_xlpm.ul,"")),_xlfn._xlws.FILTER(CHOOSE({1,2,3,4},_xlpm.ky,IF(_xlpm.fk,_xlpm.n&" → "&_xlpm.f,_xlpm.n),_xlpm.t,IF(_xlpm.nl="Yes","NULL","NOT NULL")),(_xlpm.n<>"")*(LEFT(_xlpm.n,1)<>"—")))} -> PK | W8: Id | X8: bigint | Y8: NOT NULL | AA8: DefCollateralAnnexProductScope | AB8: Id | AC8: DefCollateralAnnexMarginRule | AD8: ProductScopeId | AE8: 1:N | AF8: R02 | AG8: =IF($AF8="POLY",$AC8&".["&$AD8&"] → polymorphic (fiziksel FK yok)",$AC8&"."&$AD8&" → "&$AA8&"."&$AB8) -> DefCollateralAnnexMarginRule.ProductScopeId → DefCollateralAnnexProductScope.Id
B9: FK | C9: AnnexId → DefCollateralAnnex.Id | D9: bigint | E9: NOT NULL | G9: UQ1 | H9: AnnexCode | I9: nvarchar(50) | J9: NOT NULL | R9: Amount | S9: decimal(38,10) | T9: NOT NULL | W9: AggregateType | X9: nvarchar(40) | Y9: NOT NULL | AA9: DefCollateralAnnex | AB9: Id | AC9: DefCollateral | AD9: AnnexId | AE9: 1:N opsiyonel (nullable — standalone definition) | AF9: R03 | AG9: =IF($AF9="POLY",$AC9&".["&$AD9&"] → polymorphic (fiziksel FK yok)",$AC9&"."&$AD9&" → "&$AA9&"."&$AB9) -> DefCollateral.AnnexId → DefCollateralAnnex.Id
C10: ProductCode | D10: nvarchar(50) | E10: NOT NULL | G10: UQ1 | H10: RevisionNo | I10: int | J10: NOT NULL | R10: CurrencyCode | S10: nvarchar(3) | T10: NOT NULL | W10: AggregateId | X10: bigint | Y10: NOT NULL | AA10: DefCollateral | AB10: Id | AC10: DefCollateralEligibleCurrency | AD10: DefinitionId | AE10: 1:N · Cash için en az 1 aktif satır | AF10: R04 | AG10: =IF($AF10="POLY",$AC10&".["&$AD10&"] → polymorphic (fiziksel FK yok)",$AC10&"."&$AD10&" → "&$AA10&"."&$AB10) -> DefCollateralEligibleCurrency.DefinitionId → DefCollateral.Id
C11: SubProductCode | D11: nvarchar(50) | E11: NOT NULL | H11: AnnexName | I11: nvarchar(200) | J11: NOT NULL | R11: CurrentBalanceBefore | S11: decimal(38,10) | T11: NOT NULL | W11: EventType | X11: nvarchar(40) | Y11: NOT NULL | AA11: DefCollateral | AB11: Id | AC11: DefCollateralCashTerms | AD11: DefinitionId | AE11: 1:0..1 · yalnız CASH | AF11: R05 | AG11: =IF($AF11="POLY",$AC11&".["&$AD11&"] → polymorphic (fiziksel FK yok)",$AC11&"."&$AD11&" → "&$AA11&"."&$AB11) -> DefCollateralCashTerms.DefinitionId → DefCollateral.Id
C12: MarginType | D12: nvarchar(15) | E12: NOT NULL | H12: CustomerId | I12: int | J12: NOT NULL | R12: ValuationCurrencyCode | S12: nvarchar(3) | T12: NOT NULL | W12: ActorUser | X12: nvarchar(80) | Y12: NULL | AA12: DefCollateral | AB12: Id | AC12: DefCollateralSecurityRule | AD12: DefinitionId | AE12: 1:N · Security Scope = Rule | AF12: R06 | AG12: =IF($AF12="POLY",$AC12&".["&$AD12&"] → polymorphic (fiziksel FK yok)",$AC12&"."&$AD12&" → "&$AA12&"."&$AB12) -> DefCollateralSecurityRule.DefinitionId → DefCollateral.Id
C13: IsIncluded | D13: bit | E13: NOT NULL | H13: IsEnabled | I13: bit | J13: NOT NULL | R13: IsFxConversionRequired | S13: bit | T13: NOT NULL | W13: OccurredDate | X13: datetime | Y13: NOT NULL | AA13: DefCollateral | AB13: Id | AC13: DefCollateralSecurityISIN | AD13: DefinitionId | AE13: 1:N · Security Scope = Specific ISIN | AF13: R07 | AG13: =IF($AF13="POLY",$AC13&".["&$AD13&"] → polymorphic (fiziksel FK yok)",$AC13&"."&$AD13&" → "&$AA13&"."&$AB13) -> DefCollateralSecurityISIN.DefinitionId → DefCollateral.Id
H14: MasterAgreementText | I14: nvarchar(500) | J14: NOT NULL | R14: FxRate | S14: decimal(38,10) | T14: NOT NULL | W14: BeforeData | X14: nvarchar(MAX) | Y14: NULL | AA14: DefCollateral | AB14: Id | AC14: DefCollateralSecurityTerms | AD14: DefinitionId | AE14: 1:0..1 · yalnız SECURITY | AF14: R08 | AG14: =IF($AF14="POLY",$AC14&".["&$AD14&"] → polymorphic (fiziksel FK yok)",$AC14&"."&$AD14&" → "&$AA14&"."&$AB14) -> DefCollateralSecurityTerms.DefinitionId → DefCollateral.Id
H15: CollateralDocumentText | I15: nvarchar(500) | J15: NOT NULL | R15: FxAdjustmentRate | S15: decimal(18,10) | T15: NOT NULL | W15: AfterData | X15: nvarchar(MAX) | Y15: NULL | AA15: DefCollateral | AB15: Id | AC15: DefCollateralSettlementMap | AD15: DefinitionId | AE15: 1:N | AF15: R09 | AG15: =IF($AF15="POLY",$AC15&".["&$AD15&"] → polymorphic (fiziksel FK yok)",$AC15&"."&$AD15&" → "&$AA15&"."&$AB15) -> DefCollateralSettlementMap.DefinitionId → DefCollateral.Id
H16: BaseCurrencyCode | I16: nvarchar(3) | J16: NOT NULL | R16: TransactionValue | S16: decimal(38,10) | T16: NOT NULL | W16: CorrelationId | X16: nvarchar(80) | Y16: NULL | AA16: DefCollateral | AB16: Id | AC16: TxnCollateral | AD16: DefinitionId | AE16: 1:N · 🔴 işlem varken definition silinemez | AF16: R10 | AG16: =IF($AF16="POLY",$AC16&".["&$AD16&"] → polymorphic (fiziksel FK yok)",$AC16&"."&$AD16&" → "&$AA16&"."&$AB16) -> TxnCollateral.DefinitionId → DefCollateral.Id
H17: Direction | I17: nvarchar(20) | J17: NOT NULL | R17: AdjustedEligibleValue | S17: decimal(38,10) | T17: NOT NULL | W17: SourceIp | X17: nvarchar(64) | Y17: NULL | AA17: DefCollateralAnnex | AB17: Id | AC17: TxnCollateral | AD17: AnnexId | AE17: 1:N opsiyonel | AF17: R11 | AG17: =IF($AF17="POLY",$AC17&".["&$AD17&"] → polymorphic (fiziksel FK yok)",$AC17&"."&$AD17&" → "&$AA17&"."&$AB17) -> TxnCollateral.AnnexId → DefCollateralAnnex.Id
H18: ValidFrom | I18: date | J18: NOT NULL | W18: Channel | X18: nvarchar(30) | Y18: NULL | AA18: TxnCollateral | AB18: Id | AC18: TxnCollateralCash | AD18: TxnId | AE18: 1:1 alt tip (CASH) | AF18: R14 | AG18: =IF($AF18="POLY",$AC18&".["&$AD18&"] → polymorphic (fiziksel FK yok)",$AC18&"."&$AD18&" → "&$AA18&"."&$AB18) -> TxnCollateralCash.TxnId → TxnCollateral.Id
B19: =DefCollateralAnnexMarginRule!A1 -> DefCollateralAnnexMarginRule | H19: ValidTo | I19: date | J19: NULL | AA19: TxnCollateral | AB19: Id | AC19: TxnCollateralSecurity | AD19: TxnId | AE19: 1:1 alt tip (SECURITY) | AF19: R15 | AG19: =IF($AF19="POLY",$AC19&".["&$AD19&"] → polymorphic (fiziksel FK yok)",$AC19&"."&$AD19&" → "&$AA19&"."&$AB19) -> TxnCollateralSecurity.TxnId → TxnCollateral.Id
B20: Anahtar | C20: ="Kolon / FK hedefi ("&ROWS(_xlfn.ANCHORARRAY(B21))&")" -> Kolon / FK hedefi (8) | D20: Tip | E20: Null | H20: DisputeToleranceAmount | I20: decimal(38,10) | J20: NOT NULL | AA20: TxnCollateral | AB20: Id | AC20: TxnCollateralValuation | AD20: TxnId | AE20: 1:N · immutable | AF20: R16 | AG20: =IF($AF20="POLY",$AC20&".["&$AD20&"] → polymorphic (fiziksel FK yok)",$AC20&"."&$AD20&" → "&$AA20&"."&$AB20) -> TxnCollateralValuation.TxnId → TxnCollateral.Id
B21: {=_xlfn.LET(_xlpm.d,DefCollateralAnnexMarginRule!$A$7:$F$79,_xlpm.n,INDEX(_xlpm.d,,1),_xlpm.t,INDEX(_xlpm.d,,2),_xlpm.nl,INDEX(_xlpm.d,,3),_xlpm.c,INDEX(_xlpm.d,,5),_xlpm.f,INDEX(_xlpm.d,,6),_xlpm.pk,ISNUMBER(SEARCH("PK_",_xlpm.c))+ISNUMBER(SEARCH("(PK ile)",_xlpm.c)),_xlpm.fk,(LEFT(_xlpm.f,3)="Def")+(LEFT(_xlpm.f,3)="Txn"),_xlpm.qone,ISNUMBER(SEARCH("UQ1",_xlpm.c)),_xlpm.qtwo,ISNUMBER(SEARCH("UQ2",_xlpm.c)),_xlpm.qthree,ISNUMBER(SEARCH("UQ3",_xlpm.c)),_xlpm.uq,ISNUMBER(SEARCH("UQ",_xlpm.c)),_xlpm.ul,IF(_xlpm.qone,"UQ1",IF(_xlpm.qtwo,"UQ2",IF(_xlpm.qthree,"UQ3","UQ"))),_xlpm.ky,TRIM(IF(_xlpm.pk,"PK ","")&IF(_xlpm.fk,"FK ","")&IF(_xlpm.uq*(_xlpm.pk=0),_xlpm.ul,"")),_xlfn._xlws.FILTER(CHOOSE({1,2,3,4},_xlpm.ky,IF(_xlpm.fk,_xlpm.n&" → "&_xlpm.f,_xlpm.n),_xlpm.t,IF(_xlpm.nl="Yes","NULL","NOT NULL")),(_xlpm.n<>"")*(LEFT(_xlpm.n,1)<>"—")))} -> PK | C21: Id | D21: bigint | E21: NOT NULL | H21: DisputeToleranceCurrencyCode | I21: nvarchar(3) | J21: NOT NULL | AA21: TxnCollateral | AB21: Id | AC21: TxnCollateralLimit | AD21: TxnId | AE21: 1:N · ENTRY/VERIFY | AF21: R17 | AG21: =IF($AF21="POLY",$AC21&".["&$AD21&"] → polymorphic (fiziksel FK yok)",$AC21&"."&$AD21&" → "&$AA21&"."&$AB21) -> TxnCollateralLimit.TxnId → TxnCollateral.Id
B22: FK UQ1 | C22: ProductScopeId → DefCollateralAnnexProductScope.Id | D22: bigint | E22: NOT NULL | H22: StateId | I22: int | J22: NOT NULL | AA22: TxnCollateral | AB22: Id | AC22: TxnCollateralPaymentInstruction | AD22: TxnId | AE22: 1:N (sürümlü), aktif sürüm 1 tane | AF22: R18 | AG22: =IF($AF22="POLY",$AC22&".["&$AD22&"] → polymorphic (fiziksel FK yok)",$AC22&"."&$AD22&" → "&$AA22&"."&$AB22) -> TxnCollateralPaymentInstruction.TxnId → TxnCollateral.Id
B23: UQ1 | C23: Party | D23: nvarchar(20) | E23: NOT NULL | H23: StateMaker | I23: nvarchar(80) | J23: NOT NULL | Q23: =TxnCollateralSecurity!A1 -> TxnCollateralSecurity | AA23: TxnCollateral | AB23: Id | AC23: TxnCollateralMessage | AD23: TxnId | AE23: 1:N · idempotent | AF23: R19 | AG23: =IF($AF23="POLY",$AC23&".["&$AD23&"] → polymorphic (fiziksel FK yok)",$AC23&"."&$AD23&" → "&$AA23&"."&$AB23) -> TxnCollateralMessage.TxnId → TxnCollateral.Id
B24: UQ1 | C24: CurrencyCode | D24: nvarchar(3) | E24: NOT NULL | H24: StateDate | I24: datetime | J24: NOT NULL | Q24: Anahtar | R24: ="Kolon / FK hedefi ("&ROWS(_xlfn.ANCHORARRAY(Q25))&")" -> Kolon / FK hedefi (13) | S24: Tip | T24: Null | AA24: TxnCollateralMessage | AB24: Id | AC24: TxnCollateralMessageEvent | AD24: MessageId | AE24: 1:N · append-only | AF24: R20 | AG24: =IF($AF24="POLY",$AC24&".["&$AD24&"] → polymorphic (fiziksel FK yok)",$AC24&"."&$AD24&" → "&$AA24&"."&$AB24) -> TxnCollateralMessageEvent.MessageId → TxnCollateralMessage.Id
C25: ThresholdAmount | D25: decimal(38,10) | E25: NOT NULL | H25: CreatedBy | I25: nvarchar(80) | J25: NOT NULL | Q25: {=_xlfn.LET(_xlpm.d,TxnCollateralSecurity!$A$7:$F$80,_xlpm.n,INDEX(_xlpm.d,,1),_xlpm.t,INDEX(_xlpm.d,,2),_xlpm.nl,INDEX(_xlpm.d,,3),_xlpm.c,INDEX(_xlpm.d,,5),_xlpm.f,INDEX(_xlpm.d,,6),_xlpm.pk,ISNUMBER(SEARCH("PK_",_xlpm.c))+ISNUMBER(SEARCH("(PK ile)",_xlpm.c)),_xlpm.fk,(LEFT(_xlpm.f,3)="Def")+(LEFT(_xlpm.f,3)="Txn"),_xlpm.qone,ISNUMBER(SEARCH("UQ1",_xlpm.c)),_xlpm.qtwo,ISNUMBER(SEARCH("UQ2",_xlpm.c)),_xlpm.qthree,ISNUMBER(SEARCH("UQ3",_xlpm.c)),_xlpm.uq,ISNUMBER(SEARCH("UQ",_xlpm.c)),_xlpm.ul,IF(_xlpm.qone,"UQ1",IF(_xlpm.qtwo,"UQ2",IF(_xlpm.qthree,"UQ3","UQ"))),_xlpm.ky,TRIM(IF(_xlpm.pk,"PK ","")&IF(_xlpm.fk,"FK ","")&IF(_xlpm.uq*(_xlpm.pk=0),_xlpm.ul,"")),_xlfn._xlws.FILTER(CHOOSE({1,2,3,4},_xlpm.ky,IF(_xlpm.fk,_xlpm.n&" → "&_xlpm.f,_xlpm.n),_xlpm.t,IF(_xlpm.nl="Yes","NULL","NOT NULL")),(_xlpm.n<>"")*(LEFT(_xlpm.n,1)<>"—")))} -> PK FK | R25: TxnId → TxnCollateral.Id | S25: bigint | T25: NOT NULL | AA25: TxnCollateral | AB25: Id | AC25: TxnCollateral | AD25: ReversalOfId | AE25: 1:0..1 self | AF25: SELF | AG25: =IF($AF25="POLY",$AC25&".["&$AD25&"] → polymorphic (fiziksel FK yok)",$AC25&"."&$AD25&" → "&$AA25&"."&$AB25) -> TxnCollateral.ReversalOfId → TxnCollateral.Id
C26: MtaAmount | D26: decimal(38,10) | E26: NOT NULL | H26: CreatedDate | I26: datetime | J26: NOT NULL | R26: ISIN | S26: nvarchar(12) | T26: NOT NULL | AA26: DefCollateral | AB26: Id | AC26: TxnCollateralPosition | AD26: DefinitionId | AE26: 1:N · bakiye projeksiyonu | AF26: R12 | AG26: =IF($AF26="POLY",$AC26&".["&$AD26&"] → polymorphic (fiziksel FK yok)",$AC26&"."&$AD26&" → "&$AA26&"."&$AB26) -> TxnCollateralPosition.DefinitionId → DefCollateral.Id
C27: RoundingAmount | D27: decimal(38,10) | E27: NOT NULL | R27: Nominal | S27: decimal(38,10) | T27: NOT NULL | AA27: TxnCollateral | AB27: Id | AC27: TxnCollateralPosition | AD27: LastTxnId | AE27: 1:0..1 · son işleme opsiyonel referans | AF27: R13 | AG27: =IF($AF27="POLY",$AC27&".["&$AD27&"] → polymorphic (fiziksel FK yok)",$AC27&"."&$AD27&" → "&$AA27&"."&$AB27) -> TxnCollateralPosition.LastTxnId → TxnCollateral.Id
C28: RoundingMethod | D28: nvarchar(12) | E28: NOT NULL | R28: CurrentNominalBefore | S28: decimal(38,10) | T28: NOT NULL | AA28: (polymorphic) | AB28: — | AC28: CollateralAuditLog | AD28: AggregateId + AggregateType | AE28: Polymorphic — gerçek FK constraint mümkün değil | AF28: POLY | AG28: =IF($AF28="POLY",$AC28&".["&$AD28&"] → polymorphic (fiziksel FK yok)",$AC28&"."&$AD28&" → "&$AA28&"."&$AB28) -> CollateralAuditLog.[AggregateId + AggregateType] → polymorphic (fiziksel FK yok)
R29: Price | S29: decimal(38,10) | T29: NOT NULL | AA29: B) Dış bağımlılıklar — mevcut MM tabloları vs yeni gerekenler | AB29: 0 | AC29: 0 | AD29: 0 | AE29: 0
R30: PriceDate | S30: date | T30: NOT NULL | AA30: Kolon(lar) | AB30: Hedef | AC30: Durum | AD30: Not | AE30: 0
R31: PriceFactor | S31: decimal(18,10) | T31: NOT NULL | AA31: CustomerId (4 tabloda) | AB31: CusCustomer.Id | AC31: ✅ MM'de VAR | AD31: Counterparty = MM'in Customer kavramı. Tip: int (MM'in mevcut tipi) | AE31: 0
G32: =DefCollateral!A1 -> DefCollateral | L32: =TxnCollateral!A1 -> TxnCollateral | R32: MarketValue | S32: decimal(38,10) | T32: NOT NULL | AA32: CurrencyCode (çok sayıda) | AB32: Currency | AC32: ✅ MM'de VAR | AD32: nvarchar(3) doğal anahtar | AE32: 0
G33: Anahtar | H33: ="Kolon / FK hedefi ("&ROWS(_xlfn.ANCHORARRAY(G34))&")" -> Kolon / FK hedefi (17) | I33: Tip | J33: Null | L33: Anahtar | M33: ="Kolon / FK hedefi ("&ROWS(_xlfn.ANCHORARRAY(L34))&")" -> Kolon / FK hedefi (30) | N33: Tip | O33: Null | R33: ValuationCurrencyCode | S33: nvarchar(3) | T33: NOT NULL | AA33: PortfolioId | AB33: PrfPortfolio.Id | AC33: ✅ MM'de VAR | AD33: 🔑 Varsayılan portföy parametreden PATH ile çözülür, Code ile değil | AE33: 0
B34: =DefCollateralEligibleCurrency!A1 -> DefCollateralEligibleCurrency | G34: {=_xlfn.LET(_xlpm.d,DefCollateral!$A$7:$F$80,_xlpm.n,INDEX(_xlpm.d,,1),_xlpm.t,INDEX(_xlpm.d,,2),_xlpm.nl,INDEX(_xlpm.d,,3),_xlpm.c,INDEX(_xlpm.d,,5),_xlpm.f,INDEX(_xlpm.d,,6),_xlpm.pk,ISNUMBER(SEARCH("PK_",_xlpm.c))+ISNUMBER(SEARCH("(PK ile)",_xlpm.c)),_xlpm.fk,(LEFT(_xlpm.f,3)="Def")+(LEFT(_xlpm.f,3)="Txn"),_xlpm.qone,ISNUMBER(SEARCH("UQ1",_xlpm.c)),_xlpm.qtwo,ISNUMBER(SEARCH("UQ2",_xlpm.c)),_xlpm.qthree,ISNUMBER(SEARCH("UQ3",_xlpm.c)),_xlpm.uq,ISNUMBER(SEARCH("UQ",_xlpm.c)),_xlpm.ul,IF(_xlpm.qone,"UQ1",IF(_xlpm.qtwo,"UQ2",IF(_xlpm.qthree,"UQ3","UQ"))),_xlpm.ky,TRIM(IF(_xlpm.pk,"PK ","")&IF(_xlpm.fk,"FK ","")&IF(_xlpm.uq*(_xlpm.pk=0),_xlpm.ul,"")),_xlfn._xlws.FILTER(CHOOSE({1,2,3,4},_xlpm.ky,IF(_xlpm.fk,_xlpm.n&" → "&_xlpm.f,_xlpm.n),_xlpm.t,IF(_xlpm.nl="Yes","NULL","NOT NULL")),(_xlpm.n<>"")*(LEFT(_xlpm.n,1)<>"—")))} -> PK | H34: Id | I34: bigint | J34: NOT NULL | L34: {=_xlfn.LET(_xlpm.d,TxnCollateral!$A$7:$F$79,_xlpm.n,INDEX(_xlpm.d,,1),_xlpm.t,INDEX(_xlpm.d,,2),_xlpm.nl,INDEX(_xlpm.d,,3),_xlpm.c,INDEX(_xlpm.d,,5),_xlpm.f,INDEX(_xlpm.d,,6),_xlpm.pk,ISNUMBER(SEARCH("PK_",_xlpm.c))+ISNUMBER(SEARCH("(PK ile)",_xlpm.c)),_xlpm.fk,(LEFT(_xlpm.f,3)="Def")+(LEFT(_xlpm.f,3)="Txn"),_xlpm.qone,ISNUMBER(SEARCH("UQ1",_xlpm.c)),_xlpm.qtwo,ISNUMBER(SEARCH("UQ2",_xlpm.c)),_xlpm.qthree,ISNUMBER(SEARCH("UQ3",_xlpm.c)),_xlpm.uq,ISNUMBER(SEARCH("UQ",_xlpm.c)),_xlpm.ul,IF(_xlpm.qone,"UQ1",IF(_xlpm.qtwo,"UQ2",IF(_xlpm.qthree,"UQ3","UQ"))),_xlpm.ky,TRIM(IF(_xlpm.pk,"PK ","")&IF(_xlpm.fk,"FK ","")&IF(_xlpm.uq*(_xlpm.pk=0),_xlpm.ul,"")),_xlfn._xlws.FILTER(CHOOSE({1,2,3,4},_xlpm.ky,IF(_xlpm.fk,_xlpm.n&" → "&_xlpm.f,_xlpm.n),_xlpm.t,IF(_xlpm.nl="Yes","NULL","NOT NULL")),(_xlpm.n<>"")*(LEFT(_xlpm.n,1)<>"—")))} -> PK | M34: Id | N34: bigint | O34: NOT NULL | R34: AssetHaircutRate | S34: decimal(18,10) | T34: NOT NULL | AA34: SettlementTypeId | AB34: SettlementType.Id | AC34: ✅ MM'de VAR | AD34: Değer kümesi örtüşüyor (Gross/Netting) — yeni tablo AÇMA | AE34: 0
B35: Anahtar | C35: ="Kolon / FK hedefi ("&ROWS(_xlfn.ANCHORARRAY(B36))&")" -> Kolon / FK hedefi (4) | D35: Tip | E35: Null | G35: UQ1 | H35: CollateralCode | I35: nvarchar(50) | J35: NOT NULL | L35: UQ1 | M35: LogicalReference | N35: nvarchar(80) | O35: NOT NULL | R35: FxHaircutRate | S35: decimal(18,10) | T35: NOT NULL | AA35: PaymentInstructionTypeId | AB35: PaymentInstructionType.Id | AC35: ✅ MM'de VAR | AD35: B2B/A2A/Vostro/A2AD — yeni tablo AÇMA | AE35: 0
B36: {=_xlfn.LET(_xlpm.d,DefCollateralEligibleCurrency!$A$7:$F$79,_xlpm.n,INDEX(_xlpm.d,,1),_xlpm.t,INDEX(_xlpm.d,,2),_xlpm.nl,INDEX(_xlpm.d,,3),_xlpm.c,INDEX(_xlpm.d,,5),_xlpm.f,INDEX(_xlpm.d,,6),_xlpm.pk,ISNUMBER(SEARCH("PK_",_xlpm.c))+ISNUMBER(SEARCH("(PK ile)",_xlpm.c)),_xlpm.fk,(LEFT(_xlpm.f,3)="Def")+(LEFT(_xlpm.f,3)="Txn"),_xlpm.qone,ISNUMBER(SEARCH("UQ1",_xlpm.c)),_xlpm.qtwo,ISNUMBER(SEARCH("UQ2",_xlpm.c)),_xlpm.qthree,ISNUMBER(SEARCH("UQ3",_xlpm.c)),_xlpm.uq,ISNUMBER(SEARCH("UQ",_xlpm.c)),_xlpm.ul,IF(_xlpm.qone,"UQ1",IF(_xlpm.qtwo,"UQ2",IF(_xlpm.qthree,"UQ3","UQ"))),_xlpm.ky,TRIM(IF(_xlpm.pk,"PK ","")&IF(_xlpm.fk,"FK ","")&IF(_xlpm.uq*(_xlpm.pk=0),_xlpm.ul,"")),_xlfn._xlws.FILTER(CHOOSE({1,2,3,4},_xlpm.ky,IF(_xlpm.fk,_xlpm.n&" → "&_xlpm.f,_xlpm.n),_xlpm.t,IF(_xlpm.nl="Yes","NULL","NOT NULL")),(_xlpm.n<>"")*(LEFT(_xlpm.n,1)<>"—")))} -> PK FK | C36: DefinitionId → DefCollateral.Id | D36: bigint | E36: NOT NULL | G36: UQ1 | H36: RevisionNo | I36: int | J36: NOT NULL | L36: UQ2 | M36: TransactionReference | N36: nvarchar(60) | O36: NOT NULL | R36: FxRate | S36: decimal(38,10) | T36: NOT NULL | AA36: TraderUserId / StateMaker / CreatedBy | AB36: Kullanıcı (nvarchar(80)) | AC36: ✅ MM deseni | AD36: MM ayrı User tablosuna FK vermiyor, string tutuyor | AE36: 0
B37: PK | C37: CurrencyCode | D37: nvarchar(3) | E37: NOT NULL | H37: CollateralName | I37: nvarchar(200) | J37: NOT NULL | L37: FK | M37: DefinitionId → DefCollateral.Id | N37: bigint | O37: NOT NULL | R37: AdjustedEligibleValue | S37: decimal(38,10) | T37: NOT NULL | AA37: ProductCode, SubProductCode | AB37: Ürün kataloğu | AC37: ⚠️ NETLEŞMEDİ | AD37: MM'in PrdProductDefinition'ı hazine ürün ailesi (FX/IR/Repo) için yeterli mi? | AE37: 0
C38: FxAdjustmentRate | D38: decimal(18,10) | E38: NOT NULL | G38: FK | H38: AnnexId → DefCollateralAnnex.Id | I38: bigint | J38: NULL | L38: FK | M38: AnnexId → DefCollateralAnnex.Id | N38: bigint | O38: NULL | AA38: SettlementAccountId, InterestAccountId | AB38: Hesap master | AC38: ⚠️ NETLEŞMEDİ | AD38: MM'de hesap Fimple'dan geliyor (AccountNumber/GLCode kolonları), ayrı master yok | AE38: 0
C39: IsActive | D39: bit | E39: NOT NULL | H39: CustomerId | I39: int | J39: NOT NULL | M39: CustomerId | N39: int | O39: NOT NULL | AA39: SsiId (5 kolonda) | AB39: SSI master | AC39: 🔴 YENİ GEREKLİ | AD39: MM'de yok. Collateral içinde mi, ortak modülde mi? | AE39: 0
H40: CollateralType | I40: nvarchar(12) | J40: NOT NULL | M40: PortfolioId | N40: int | O40: NOT NULL | AA40: ISIN, SecurityTypeCode, IssuerTypeCode, MinimumRatingCode | AB40: Menkul kıymet master | AC40: 🔴 YENİ GEREKLİ | AD40: Collateral'ın en büyük dış bağımlılığı | AE40: 0
H41: IsEnabled | I41: bit | J41: NOT NULL | L41: UQ3 | M41: SourceSystem | N41: nvarchar(50) | O41: NULL | AA41: SettlementLocationCode | AB41: CSD/ICSD kataloğu | AC41: 🔴 YENİ GEREKLİ | AD41: Takasbank/Euroclear/Clearstream | AE41: 0
H42: EligibilityDirection | I42: nvarchar(20) | J42: NOT NULL | L42: UQ3 | M42: ExternalReference | N42: nvarchar(100) | O42: NULL | AA42: PaymentRouteCode | AB42: Ödeme rota konfigürasyonu | AC42: 🔴 YENİ GEREKLİ | AD42: pacs.009 / MT202 / local route seçimi | AE42: 0
...

Sheet DefCollateralAnnex
A1: DefCollateralAnnex | B1: (doküman adı: collateral_annex)
A2: Annex ekranı ana tablosu — sözleşmesel çerçeve. Her değişiklik yeni revizyon satırı (AnnexCode + RevisionNo), mevcut satır UPDATE edilmez.
A4: DB NESNELERİ: | B4: ✅ History + Trigger ZORUNLU (DefCollateralAnnexHistory + DefCollateralAnnexTrigger) · Id: bigint IDENTITY(1,1) · sp_UnverifiedDataCount + DefCountMonitoring (ekran rozetinde görünecekse)
A6: Kolon Adı | B6: Tip | C6: Null | D6: Default | E6: Index / Constraint | F6: FK Hedefi (FK → PK) | G6: Açıklama | H6: Anahtar / Açık Eşleşme
A7: Id | B7: bigint | C7: No | D7: IDENTITY(1,1) | E7: PK_DefCollateralAnnex | G7: 🔑 v4: IDENTITY. EF config'te `.UseIdentityColumn()` AÇIKÇA yazılmalı — yazılmazsa EF convention'ı int PK'yı ValueGeneratedOnAdd sayıp insert'i patlatıyor (MM'de ProductDefinition Create yolu bu yüzden kırık) | H7: PK
A8: AnnexCode | B8: nvarchar(50) | C8: No | E8: UQ1 · UQ_DefCollateralAnnex_AnnexCode | G8: Kullanıcıya gösterilen sabit iş kodu | H8: UQ1
A9: RevisionNo | B9: int | C9: No | D9: DEFAULT (1) | E9: (UQ1 ile birlikte) | G9: Sözleşmesel revizyon no — 🔴 MM'de emsali olmayan yeni pattern | H9: UQ1
A10: AnnexName | B10: nvarchar(200) | C10: No | G10: Açıklayıcı ad
A11: CustomerId | B11: int | C11: No | E11: IX_DefCollateralAnnex_CustomerId | F11: CusCustomer.Id | G11: Counterparty | H11: FK → CusCustomer.Id (PK)
A12: IsEnabled | B12: bit | C12: No | D12: DEFAULT (1) | E12: DF_DefCollateralAnnex_IsEnabled | G12: 🔑 v4: `Status` (DRAFT/ACTIVE/INACTIVE) KALDIRILDI — DRAFT≈StateId 16, ACTIVE≈StateId 18, yani %70'i tekrardı. Karşılığı olmayan tek değer INACTIVE idi; onu MM'in standart `IsEnabled` deseni karşılıyor (23 tabloda var). Kullanılabilirlik testi: `(StateId & 2) = 2 AND IsEnabled = 1`
A13: MasterAgreementText | B13: nvarchar(500) | C13: No | G13: Free-format sözleşme adı
A14: CollateralDocumentText | B14: nvarchar(500) | C14: No | G14: Free-format teminat dokümanı
A15: BaseCurrencyCode | B15: nvarchar(3) | C15: No | F15: Currency | G15: Raporlama/değerleme para birimi | H15: FK → Currency (doğal anahtar)
A16: Direction | B16: nvarchar(20) | C16: No | G16: BOTH / POST_ONLY / RECEIVE_ONLY
A17: ValidFrom | B17: date | C17: No | G17: Revizyon başlangıcı
A18: ValidTo | B18: date | C18: Yes | G18: Boşsa açık uçlu · ValidTo >= ValidFrom
A19: DisputeToleranceAmount | B19: decimal(38,10) | C19: No | D19: DEFAULT (0) | G19: Uyuşmazlık toleransı
A20: DisputeToleranceCurrencyCode | B20: nvarchar(3) | C20: No | F20: Currency | G20: Tolerans para birimi | H20: FK → Currency (doğal anahtar)
A21: StateId | B21: int | C21: No | D21: DEFAULT (18) | E21: DF_DefCollateralAnnex_StateId · IX_DefCollateralAnnex_StateId | G21: MakerChecker StateId (int, bitmask). Annex kullanılabilirliği `(StateId & 2) = 2 AND IsEnabled = 1` ile belirlenir; ayrı Status kolonu yoktur.
A22: StateMaker | B22: nvarchar(80) | C22: No | D22: DEFAULT ('system') | E22: DF_DefCollateralAnnex_StateMaker | G22: Son durum değişikliğini yapan kullanıcı (MakerCheckerEntity)
A23: StateDate | B23: datetime | C23: No | D23: DEFAULT (getdate()) | E23: DF_DefCollateralAnnex_StateDate | G23: Son durum değişikliği zamanı (MakerCheckerEntity)
A24: CreatedBy | B24: nvarchar(80) | C24: No | D24: DEFAULT (N'') | E24: DF_DefCollateralAnnex_CreatedBy | G24: ⚠️ MakerCheckerEntity bu alanı DECLARE ETMİYOR — entity sınıfına elle eklenmeli (doküman §10 her tabloda created_by istiyor)
A25: CreatedDate | B25: datetime | C25: No | D25: DEFAULT (getdate()) | E25: DF_DefCollateralAnnex_CreatedDate | G25: ⚠️ MakerCheckerEntity'de YOK — entity'ye elle eklenir

Sheet DefCollateralAnnexProductScope
A1: DefCollateralAnnexProductScope | B1: (doküman adı: annex_product_scope)
A2: Add Product penceresi — Annex kapsamındaki Product + SubProduct + MarginType kombinasyonu.
